<?xml version='1.0' encoding='utf-8'?>
<robot name="A02L-M1">
  
  <joint name="joint1" type="revolute">
    <parent link="base_link" />
    <child link="link1" />
    <origin rpy="0.0 0.0 -3.141592653589793" xyz="0.0 0.0 0.155" />
    <axis xyz="0 0 1" />
    <limit effort="123" lower="-2.7925" upper="2.7925" velocity="2.0944" />
    <safety_controller k_position="100.0" k_velocity="40.0" soft_lower_limit="-2.7663" soft_upper_limit="2.7663" />
    <flexiv>
      <mdh_to_rca_coordinate_transform>
        <offset>0</offset>
        <direction>1</direction>
      </mdh_to_rca_coordinate_transform>
    </flexiv>
  </joint>
  <joint name="joint2" type="revolute">
    <parent link="link1" />
    <child link="link2" />
    <origin rpy="0.0 0.0 0.0" xyz="0.0 0.03 0.21" />
    <axis xyz="0 1 0" />
    <limit effort="123" lower="-2.2689" upper="2.2689" velocity="2.0944" />
    <safety_controller k_position="100.0" k_velocity="40.0" soft_lower_limit="-2.2427" soft_upper_limit="2.2427" />
    <flexiv>
      <mdh_to_rca_coordinate_transform>
        <offset>0</offset>
        <direction>1</direction>
      </mdh_to_rca_coordinate_transform>
    </flexiv>
  </joint>
  <joint name="joint3" type="revolute">
    <parent link="link2" />
    <child link="link3" />
    <origin rpy="0.0 0.0 0.0" xyz="0.0 0.035 0.205" />
    <axis xyz="0 0 1" />
    <limit effort="64" lower="-2.9671" upper="2.9671" velocity="2.4435" />
    <safety_controller k_position="100.0" k_velocity="40.0" soft_lower_limit="-2.9409" soft_upper_limit="2.9409" />
    <flexiv>
      <mdh_to_rca_coordinate_transform>
        <offset>0</offset>
        <direction>1</direction>
      </mdh_to_rca_coordinate_transform>
    </flexiv>
  </joint>
  <joint name="joint4" type="revolute">
    <parent link="link3" />
    <child link="link4" />
    <origin rpy="0.0 0.0 -3.141592653589793" xyz="-0.02 -0.03 0.19" />
    <axis xyz="0 1 0" />
    <limit effort="64" lower="-1.8675" upper="2.6878" velocity="2.4435" />
    <safety_controller k_position="100.0" k_velocity="40.0" soft_lower_limit="-1.8413" soft_upper_limit="2.6616" />
    <flexiv>
      <mdh_to_rca_coordinate_transform>
        <offset>0</offset>
        <direction>1</direction>
      </mdh_to_rca_coordinate_transform>
    </flexiv>
  </joint>
  <joint name="joint5" type="revolute">
    <parent link="link4" />
    <child link="link5" />
    <origin rpy="0.0 0.0 -3.141592653589793" xyz="-0.02 0.025 0.195" />
    <axis xyz="0 0 1" />
    <limit effort="39" lower="-2.9671" upper="2.9671" velocity="4.8869" />
    <safety_controller k_position="100.0" k_velocity="40.0" soft_lower_limit="-2.9409" soft_upper_limit="2.9409" />
    <flexiv>
      <mdh_to_rca_coordinate_transform>
        <offset>0</offset>
        <direction>1</direction>
      </mdh_to_rca_coordinate_transform>
    </flexiv>
  </joint>
  <joint name="joint6" type="revolute">
    <parent link="link5" />
    <child link="link6" />
    <origin rpy="0.0 0.0 0.0" xyz="0.0 0.03 0.19" />
    <axis xyz="0 1 0" />
    <limit effort="39" lower="-1.3963" upper="4.5379" velocity="4.8869" />
    <safety_controller k_position="100.0" k_velocity="40.0" soft_lower_limit="-1.3701" soft_upper_limit="4.5117" />
    <flexiv>
      <mdh_to_rca_coordinate_transform>
        <offset>-1.5707963267948966</offset>
        <direction>1</direction>
      </mdh_to_rca_coordinate_transform>
    </flexiv>
  </joint>
  <joint name="joint7" type="revolute">
    <parent link="link6" />
    <child link="link7" />
    <origin rpy="0.0 -1.5707963478683205 0.0" xyz="-0.055 0.07 0.11" />
    <axis xyz="0 0 1" />
    <limit effort="39" lower="-2.9671" upper="2.9671" velocity="4.8869" />
    <safety_controller k_position="100.0" k_velocity="40.0" soft_lower_limit="-2.9409" soft_upper_limit="2.9409" />
    <flexiv>
      <mdh_to_rca_coordinate_transform>
        <offset>0</offset>
        <direction>1</direction>
      </mdh_to_rca_coordinate_transform>
    </flexiv>
  </joint>
  <joint name="link7_to_flange" type="fixed">
    <parent link="link7" />
    <child link="flange" />
    <origin rpy="0.0 0.0 -3.141592653589793" xyz="0.0 0.0 0.081" />
  </joint>
  
  <link name="base_link">
    <inertial>
      <mass value="3.653" />
      <origin rpy="0 0 0" xyz="0.0002 -0.0006 0.0874" />
      <inertia ixx="0.0194" ixy="0.0" ixz="0.0" iyy="0.0196" iyz="0.0001" izz="0.0088" />
    </inertial>
    <visual>
      <origin rpy="0 0 0" xyz="0 0 0" />
      <geometry>
        <mesh filename="package://flexiv_description/meshes/A02L-M1/visual/link0.obj" />
      </geometry>
    </visual>
    <collision>
      <origin rpy="0 0 0" xyz="0 0 0" />
      <geometry>
        <mesh filename="package://flexiv_description/meshes/A02L-M1/collision/link0.obj" />
      </geometry>
    </collision>
  </link>
  <link name="link1">
    <inertial>
      <mass value="3.673" />
      <origin rpy="0 0 0" xyz="0.0001 0.006 0.1489" />
      <inertia ixx="0.0276" ixy="0.0" ixz="0.0" iyy="0.0272" iyz="0.0017" izz="0.0077" />
    </inertial>
    <visual>
      <origin rpy="0 0 0" xyz="0 0 0" />
      <geometry>
        <mesh filename="package://flexiv_description/meshes/A02L-M1/visual/link1.obj" />
      </geometry>
    </visual>
    <collision>
      <origin rpy="0 0 0" xyz="0 0 0" />
      <geometry>
        <mesh filename="package://flexiv_description/meshes/A02L-M1/collision/link1.obj" />
      </geometry>
    </collision>
  </link>
  <link name="link2">
    <inertial>
      <mass value="2.734" />
      <origin rpy="0 0 0" xyz="0.0002 0.0362 0.0979" />
      <inertia ixx="0.0234" ixy="0.0" ixz="0.0" iyy="0.0243" iyz="-0.0003" izz="0.0036" />
    </inertial>
    <visual>
      <origin rpy="0 0 0" xyz="0 0 0" />
      <geometry>
        <mesh filename="package://flexiv_description/meshes/A02L-M1/visual/link2.obj" />
      </geometry>
    </visual>
    <collision>
      <origin rpy="0 0 0" xyz="0 0 0" />
      <geometry>
       <mesh filename="package://flexiv_description/meshes/A02L-M1/collision/link2.obj" />
      </geometry>
    </collision>
  </link>
  <link name="link3">
    <inertial>
      <mass value="2.397" />
      <origin rpy="0 0 0" xyz="-0.0117 -0.0028 0.1334" />
      <inertia ixx="0.0141" ixy="0.0001" ixz="-0.0014" iyy="0.0137" iyz="-0.0007" izz="0.0038" />
    </inertial>
    <visual>
      <origin rpy="0 0 0" xyz="0 0 0" />
      <geometry>
        <mesh filename="package://flexiv_description/meshes/A02L-M1/visual/link3.obj" />
      </geometry>
    </visual>
    <collision>
      <origin rpy="0 0 0" xyz="0 0 0" />
      <geometry>
        <mesh filename="package://flexiv_description/meshes/A02L-M1/collision/link3.obj" />
      </geometry>
    </collision>
  </link>
  <link name="link4">
    <inertial>
      <mass value="2.397" />
      <origin rpy="0 0 0" xyz="-0.0126 0.0312 0.1013" />
      <inertia ixx="0.0184" ixy="0.0001" ixz="-0.0016" iyy="0.0188" iyz="-0.0012" izz="0.003" />
    </inertial>
    <visual>
      <origin rpy="0 0 0" xyz="0 0 0" />
      <geometry>
        <mesh filename="package://flexiv_description/meshes/A02L-M1/visual/link4.obj" />
      </geometry>
    </visual>
    <collision>
      <origin rpy="0 0 0" xyz="0 0 0" />
      <geometry>
        <mesh filename="package://flexiv_description/meshes/A02L-M1/collision/link4.obj" />
      </geometry>
    </collision>
  </link>
  <link name="link5">
    <inertial>
      <mass value="2.363" />
      <origin rpy="0 0 0" xyz="-0.0002 0.0032 0.1328" />
      <inertia ixx="0.014" ixy="0.0" ixz="0.0" iyy="0.0134" iyz="0.0007" izz="0.0036" />
    </inertial>
    <visual>
      <origin rpy="0 0 0" xyz="0 0 0" />
      <geometry>
        <mesh filename="package://flexiv_description/meshes/A02L-M1/visual/link5.obj" />
      </geometry>
    </visual>
    <collision>
      <origin rpy="0 0 0" xyz="0 0 0" />
      <geometry>
        <mesh filename="package://flexiv_description/meshes/A02L-M1/collision/link5.obj" />
      </geometry>
    </collision>
  </link>
  <link name="link6">
    <inertial>
      <mass value="2.135" />
      <origin rpy="0 0 0" xyz="-0.0092 0.0567 0.0694" />
      <inertia ixx="0.0083" ixy="-0.0003" ixz="-0.0008" iyy="0.0086" iyz="0.0018" izz="0.0036" />
    </inertial>
    <visual>
      <origin rpy="0 0 0" xyz="0 0 0" />
      <geometry>
        <mesh filename="package://flexiv_description/meshes/A02L-M1/visual/link6.obj" />
      </geometry>
    </visual>
    <collision>
      <origin rpy="0 0 0" xyz="0 0 0" />
      <geometry>
        <mesh filename="package://flexiv_description/meshes/A02L-M1/collision/link6.obj" />
      </geometry>
    </collision>
  </link>
  <link name="link7">
    <inertial>
      <mass value="0.793" />
      <origin rpy="0 0 0" xyz="0.0 -0.0003 0.025" />
      <inertia ixx="0.0009" ixy="0.0" ixz="0.0" iyy="0.001" iyz="0.0" izz="0.0009" />
    </inertial>
    <visual>
      <origin rpy="0 0 0" xyz="0 0 0" />
      <geometry>
        <mesh filename="package://flexiv_description/meshes/A02L-M1/visual/link7.obj" />
      </geometry>
    </visual>
    <collision>
      <origin rpy="0 0 0" xyz="0 0 0" />
      <geometry>
        <mesh filename="package://flexiv_description/meshes/A02L-M1/collision/link7.obj" />
      </geometry>
    </collision>
  </link>
  <link name="flange">
    <inertial>
      <mass value="0.0" />
      <origin rpy="0 0 0" xyz="0.0 0.0 0.0" />
      <inertia ixx="0.0" ixy="0.0" ixz="0.0" iyy="0.0" iyz="0.0" izz="0.0" />
    </inertial>
  </link>
  <material name="rizon_blue">
    <color rgba="0. 0. 1. 0.5" />
  </material>
  <material name="rizon_light_grey">
    <color rgba="0.9 0.9 0.9 1" />
  </material>
  <material name="rizon_dark_grey">
    <color rgba="0.2 0.2 0.2 1" />
  </material>
  <material name="rizon_white">
    <color rgba="1 1 1 1" />
  </material>
</robot>